Workbook
Name Slicer_County: #N/A

Sheet Term 2 Population Data Colle...
A1: Date | B1: County | C1: Region | D1: Subregion | E1: School | G1: Please select your role | H1: What is your role/title? | I1: Which mode of data collection in Kobo did you use? | J1: Ranking | K1: How would you rate the overall data collection process? | L1: How would you rate the overall use of the tool? | M1: What went well? | N1: What could have been better? | O1: How can we improve? | P1: Any other notes or comments
A2: 46178 | B2: KIAMBU | C2: KIAMBU CENTRAL | D2: LIMURU 1 | E2: NYATARAGI PRIMARY - 9be87a9e-1890-4d96-a065-46cd82ef5772 | G2: SL/SC | I2: Online (Link) | K2: Good | L2: Good | M2: I was able to collect data on time so easily | N2: Getting the baseline population | O2: N.A | W2: =COUNTBLANK('clean data'!O2:O590) -> 86
A3: 46178 | B3: KISUMU | C3: WESTERN - KISUMU | D3: KISUMU | E3: ST. JOHN PAUL KUDHO PRIMARY, ECDE AND JUNIOR SECONDARY - 37f21ffd-63f8-4210-91d8-14b6618939e3 | G3: SL/SC | I3: Online (Link) | K3: Very Good | L3: Very Good | M3: It's very fast | N3: None | O3: We should be given enough time | P3: Good work
A4: 46178 | B4: KIAMBU | C4: KIAMBU WEST | D4: KIKUYU | E4: WAMBAA PRIMARY SCHOOL - 6eb9b529-26ed-4951-94ac-a0c02dc126b7 | G4: SL/SC | I4: Online (Link) | K4: Good | L4: Good | M4: Summation of the total students were done automatically | N4: The daily attendance report has been quite tricky to take since not all teachers are ready to cooperate.One day I went to get the attendance and was told attendance is same as yesterday yet the class had alot of empty seats. | O4: Simple totals section instead of the boys and girls totals.
A5: 46178 | B5: KIAMBU | C5: KIAMBU EAST | D5: KIAMBU | E5: KANGOYA PRIMARY AND JUNIOR SCHOOL - a38f6992-2295-4610-8322-a62a291c5917 | G5: SL/SC | I5: Online (Link) | K5: Good | L5: Good | M5: Great cooperation with the administration | N5: High rates of Abesentim really affects the accuracy of the data collected | O5: Good relations for accurate data with the administration
A6: 46178 | B6: KIAMBU | C6: KIAMBU WEST | D6: KIKUYU | E6: GIKAMBURA PRIMARY AND JUNIOR SCHOOL - 59c577e8-b581-44c2-8469-8447a39563a5 | G6: SL/SC | I6: Offline (Used the app) | K6: Good | L6: Good | M6: Seamless navigation. | N6: GPS location was challenging. | O6: N/A
A7: 46178 | B7: KAJIADO | C7: NAIROBI WEST | D7: KAJIADO-LANGATA | E7: NGONG TOWNSHIP COMPREHENSIVE - f98dd2fc-dbd5-4861-a488-d913d4373c02 | G7: SL/SC | I7: Online (Link) | K7: Very Good | L7: Very Good | M7: Easier to use | N7: I like the layout.No suggestion | O7: All is well | P7: No comment
A8: 46178 | B8: KIAMBU | C8: KIAMBU EAST | D8: RUIRU-JUJA | E8: ATHENA PRIMARY AND JUNIOR SECONDARY SCHOOL - 528d5744-6bda-428c-a146-97801509e900 | G8: SL/SC | I8: Offline (Used the app) | K8: Very Good | L8: Very Good | M8: It's easy to use as I just key in the number of kids in every class and it calculate the overall population | N8: The app is friendly and easy to use | O8: It would be nice if we could receive airtime during the period of data collection and other assignments so as it can be efficient more
A9: 46178 | B9: KIAMBU | C9: KIAMBU WEST | D9: KABETE | E9: RUKUBI COMPREHENSIVE SCHOOL - b5ae1034-a416-49b9-9c84-5d8a8e2907b3 | G9: SL/SC | I9: Offline (Used the app) | K9: Very Good | L9: Very Good | M9: It was an easy task | N9: Everything was ok on my side | O9: Nothing so far | P9: N/A
A10: 46178 | B10: KIAMBU | C10: KIAMBU EAST | D10: RUIRU-GITHUNGURI | E10: ST. GEORGE'S COMPREHENSIVE SCHOOL - RUIRU - 685a09dc-9347-4783-9f6e-217f523e955c | G10: SL/SC | I10: Online (Link) | K10: Good | L10: Good | M10: It was easy to use | N10: Ensure smooth transfer where when you send the data it doesn’t take you back to start afresh | O10: Ensure smooth running
A11: 46178 | B11: KAKAMEGA | C11: WESTERN - KAKAMEGA | D11: KAKAMEGA | E11: MWIYALA COMPREHENSIVE PRIMARY - 45fbb32c-9d08-47a1-be02-86fad952f6ba | G11: SL/SC | I11: Offline (Used the app) | K11: Good | L11: Good | M11: It's fast and more convenient | N11: Logging in sometimes is a problem | O11: Saving logging in details to avoid going through the whole process again when you want to feed in data | P11: N/A
A12: 46178 | B12: KIAMBU | C12: KIAMBU CENTRAL | D12: LIMURU 1 | E12: THIGIO PRIMARY SCHOOL - c4a5a62d-cea9-4bc4-a00e-7d46afe11d41 | G12: SL/SC | I12: Online (Link) | K12: Good | L12: Good | M12: It's quite easy to maneuver. And one cannot loose data once you leave the site. | N12: I was unable to access the maps coordinates on my phone thus had to use the terminal | O12: N/A | P12: N/A
A13: 46178 | B13: NAIROBI | C13: NAIROBI EAST | D13: EMBAKASI | E13: NCC EMBAKASI COMPREHENSIVE SCHOOL - b172881a-b3d3-4145-8c08-7d9c50334de7 | G13: SL/SC | I13: Offline (Used the app) | K13: Good | L13: Good | M13: The process of collecting was made easy because the documents were available | N13: Co ordination among teachers when collecting the registers | O13: Easy acquiring of the registers, | P13: None
A14: 46178 | B14: KAJIADO | C14: NAIROBI WEST | D14: KAJIADO-LANGATA | E14: OLOOLUA COMPREHENSIVE SCHOOL - 1f13a6ea-cdca-4150-95ce-f59e3734df46 | G14: SL/SC | I14: Online (Link) | K14: Good | L14: Very Good | M14: Comparing the total daily attendance and the total meals served daily as it is crucial to find the percentage of feeding kids. | N14: Collection of daily school attendance is challenging as some teachers don't update their registers daily. | O14: All is good. | P14: None.
A15: 46178 | B15: NAIROBI | C15: NAIROBI EAST | D15: EMBAKASI | E15: NAIROBI SOUTH PRIMARY - ec26124e-e324-48c0-a811-ed306d0aa4fe | G15: SL/SC | I15: Online (Link) | K15: Good | L15: Good | M15: Everything went on well without any hitches experienced. | N15: N/A | O15: N/A | P15: None
A16: 46178 | B16: NAIROBI | C16: NAIROBI EAST | D16: KASARANI | E16: TOM MBOYA PRIMARY AND JUNIOR SECONDRAY SCHOOL - 9b5b7024-b8e4-4b4b-b368-f06aabd56727 | G16: SL/SC | I16: Online (Link) | K16: Good | L16: Good | M16: Thwe option for entering just the total beside per class population | N16: Excluding the baseline population | O16: Exclude the baseline population | P16: So far so good
A17: 46178 | B17: KIAMBU | C17: KIAMBU EAST | D17: RUIRU-JUJA | E17: ST. FRANCIS MUGAI COMPREHENSIVE PRIMARY - 3ce53765-0450-4643-bd02-269a731cb199 | G17: SL/SC | I17: Offline (Used the app) | K17: Good | L17: Very Good | M17: The app was really efficient | N17: Collecting the registers, some teachers took long to submit | O17: An official document highlighting why we need the register could help speed up the process
A18: 46178 | B18: KIAMBU | C18: KIAMBU CENTRAL | D18: GITHUNGURI 1 | E18: GATHAITHI SECONDARY SCHOOL - 255cffef-41e6-4022-a3fa-de2fbe03ca3d | G18: Highschool Tapper | I18: Online (Link) | K18: Good | L18: Good | M18: I was enable to notice the overall school attendance per day | N18: If the population was more | O18: Create a site where we could get the percentage of attending students over the school's total population | P18: None
A19: 46178 | B19: MOMBASA | C19: COAST | D19: NYALI - MOMBASA | E19: BEDZIMBA COMPREHENSIVE SCHOOL - 41ba099b-2ca5-4603-b61f-e128fd0adaa4 | G19: SL/SC | I19: Offline (Used the app) | K19: Good | L19: Very Good | M19: Data was captured fast, but it would save time and accuracy if most of the parts were put in the same page i.e categorised into ECD, primary and junior school. | N19: A fewer pages would be great | O19: Compile the pages to make them a few ,like ECD pages, primary page,and jss page. | P19: All went well ✅👏🏿
A20: 46178 | B20: KIAMBU | C20: KIAMBU WEST | D20: KIKUYU | E20: P.C.E.A MAMA NGINA KENYATTA COMPREHENSIVE - 3b4154e1-4c19-449e-adbe-a0fb51714f9d | G20: SL/SC | I20: Offline (Used the app) | K20: Good | L20: Good | M20: That's a good tracking of the feeding growth | N20: For me the head of institution declined to give me population thus requesting for a better communication with the head of institution for a professional documents to support the population collection | O20: In the schools that are declining to give the population then there should be a more conquering documents to request for a population | P20: No
A21: 46178 | B21: MOMBASA | C21: COAST | D21: NYALI - MOMBASA | E21: KONGOWEA PRIMARY SCHOOL - e180a289-0e43-4117-b925-e9a571ec3723 | G21: SL/SC | I21: Online (Link) | K21: Very Good | L21: Very Good | M21: It was so accurate. | N21: Apart from it being efficient and fast ... I don't see any change that will make it more better than it is at the moment. | O21: Everything is top-notch.. thank you team. | P21: All is well
A22: 46178 | B22: MOMBASA | C22: COAST | D22: NYALI - MOMBASA | E22: MTOPANGA COMPREHENSIVE SCHOOL - a30e43e4-ec3e-4e0c-a53c-1b37ae9635c1 | G22: SL/SC | I22: Offline (Used the app) | K22: Very Good | L22: Very Good | M22: Everything went well,the application is user friendly and the fact that you can save the data and edit before submitting that helps us so much | N22: Every thing was better on my side | O22: N/A
A23: 46178 | B23: NAIROBI | C23: NAIROBI EAST | D23: KASARANI | E23: CHELETA PRIMARY SCHOOL - a68bf13e-0d4c-4027-80ef-d68df2e5fddb | G23: SL/SC | I23: Online (Link) | K23: Good | L23: Good | M23: At some point i could, my school location was not picking the latitude .the location pick up was the major hinderance | N23: App is clear and to the point | O23: Enhance quick access for location. | P23: Good collection tool.
A24: 46178 | B24: NAIROBI | C24: NAIROBI WEST | D24: KIBRA-WESTLANDS | E24: ARYA PRIMARY SCHOOL - 1237de6d-87e5-4684-826d-c39a62256eb2 | G24: SL/SC | I24: Online (Link) | K24: Very Good | L24: Very Good | M24: The process was easy by the help of the kopo data collection tool, it was easy because after getting the data from the admin, I was only feeding it to the tool. | N24: Maybe next time you give us more time because, sometimes after collecting data you find that there are other students who wants to be admitted in school. Maybe next time we should submit data after midterm | O24: Add more time to the data collection exercise | P24: It was a smooth exercise
A25: 46178 | B25: MOMBASA | C25: COAST | D25: NYALI - MOMBASA | E25: AZHAR SHARRIF COMPREHENSIVE SCHOOL - 5120ef21-54c3-4761-9f55-6de14fc8afae | G25: SL/SC | I25: Online (Link) | K25: Very Good | L25: Very Good | M25: the whole process went well | N25: N/A | O25: Scale fusion is preventing the use of Kobocollect
A26: 46178 | B26: MOMBASA | C26: COAST | D26: GOME - MOMBASA | E26: LONGO PRIMARY SCHOOL - d1229365-3e34-4c2f-b6e4-4a16f1bac01a | G26: SL/SC | I26: Online (Link) | K26: Good | L26: Good | M26: Teachers cooperation was of top notch | N26: The app had problem in submitting the data | O26: Make it better
A27: 46178 | B27: BUNGOMA | C27: WESTERN - BUNGOMA | D27: BUNGOMA | E27: SIRITANYI RC COMPREHENSIVE SCHOOL - 5e64ac8f-8770-4ec5-ad3c-c2e5d31034cb | G27: SL/SC | I27: Offline (Used the app) | K27: Very Good | L27: Very Good | M27: This round it was sufficient, no more searching errors unlike the one we used in first term | N27: Transfers of kids, coming in and some some getting to other schools | O27: It should capture longitude anywhere,as long as you are in school compound not necessarily at the gate. | P27: N/A
A28: 46178 | B28: KIAMBU | C28: KIAMBU WEST | D28: KIKUYU | E28: NGURIUNDITU PRIMARY AND JUNIOR SCHOOL - 7b6eadba-2868-4967-911b-f7b6e46beba2 | G28: SL/SC | I28: Online (Link) | K28: Good | L28: Good | M28: Mine was fast.although I haven't tried doing it offline. | N28: It would be better if you asked us the overall number instead of ' number of boys and girls per class'. | O28: Already said in the previous question. | P28: Collecting the data daily is not working since we are being asked too much questions and it's becoming hectic , I propose we collect data may be once per month .
A29: 46178 | B29: MOMBASA | C29: COAST | D29: NYALI - MOMBASA | E29: MAWENI PRIMARY SCHOOL - df2872ff-b971-48a6-839c-32640be62ebc | G29: SL/SC | I29: Offline (Used the app) | K29: Very Good | L29: Very Good | M29: It was easy.the location was easy to allocate. | N29: None | O29: All was well | P29: It easy to operate and easy to understand
A30: 46178 | B30: KIAMBU | C30: KIAMBU CENTRAL | D30: LIMURU 1 | E30: TIEKUNU PRIMARY SCHOOL - 29cf51a0-aa46-4ed4-9c19-2014964f3670 | G30: SL/SC | I30: Offline (Used the app) | K30: Very Good | L30: Good | M30: Automatic calculation of numbers.easy to use both online and offline.saves unsent data in drafts to load later. | N30: Using offline maps since no easy offline from exact location | O30: So far so good,its easy to use | P30: None
A31: 46178 | B31: KISUMU | C31: WESTERN - KISUMU | D31: KISUMU | E31: KIBOS PRISON COMPREHENSIVE SCHOOL - 1ef6ff1c-475d-48d8-8a39-ca531bcc5ad9 | G31: SL/SC | I31: Offline (Used the app) | K31: Very Good | L31: Very Good | M31: The Kobo app is faster and easier to use since you can still save your work as draft and come back to continue. | N31: Improve on location pick up the app was a bit slower on picking the GPS. | O31: No recommendations for now. | P31: Collection of data has been made more easier compared to previous times were we had to take pictures from registers and scan then send.
A32: 46178 | B32: MOMBASA | C32: COAST | D32: NYALI - MOMBASA | E32: KISAUNI PRIMARY SCHOOL - 25ff122b-b892-4904-8b7c-cb9d74a7e1a0 | G32: SL/SC | I32: Offline (Used the app) | K32: Good | L32: Good | M32: Easy to use | N32: Accessibility was a bit hard at first. | O32: N/A | P32: None
A33: 46178 | B33: KIAMBU | C33: KIAMBU CENTRAL | D33: GITHUNGURI 2 | E33: KAMONDO PRIMARY AND JUNIOR SCHOOL - 085e4d09-08f2-4ee0-bb02-19a68da34b17 | G33: SL/SC | I33: Online (Link) | K33: Very Good | L33: Very Good | M33: The link is easier to use compared to the app. It provides a more direct process, as users can submit the form immediately after completing the required fields, without having to save it first before sending. | N33: N/A | O33: N/A | P33: No.
A34: 46178 | B34: NAIROBI | C34: NAIROBI WEST | D34: KIBRA-WESTLANDS | E34: ARYA PRIMARY SCHOOL - 1237de6d-87e5-4684-826d-c39a62256eb2 | G34: SL/SC | I34: Online (Link) | K34: Very Good | L34: Very Good | M34: The exercise was easy by the help of the kopo tool. | N34: It could be even better if u extended the data collection exercise to after midterm so as to capture all the students, some get admitted late | O34: Add more time to the exercise | P34: It was a smooth process
A35: 46178 | B35: NAIROBI | C35: NAIROBI EAST | D35: KASARANI | E35: DANDORA 1 PRIMARY AND JUNIOR SCHOOL - b9f3d61b-d58d-4d64-ac42-3db4d66eb585 | G35: SL/SC | I35: Online (Link) | K35: Poor | L35: Poor | M35: I was able to feed all the population data. | N35: I worked with the kobo app at first, after filling all the detailsand tried to submit, I got an error saying form is not active. Getting school GPS wasn't easier despite the fact that I was standing right at the school gate, I'm not even sure if the coordinates sent were accurate. After resorting to the online form, the major challenge was that I couldn't see what I was selecting as region, subregion and school, it's best if the wording appear clearly, not just some random circles. | O35: When you update the population collection tool on the app, please do us the courtesy of informing us so we can update as required. On the attachment, allow inclusion of more than 1 file type as well as multiple files, I didn't attach the evidence given by the ECDE Manager because there was no way to add it. In the list of source of information, you left out the ECDE manager, yet they are crucial in information provision, again, allow us to choose more than 1 source of information. I personally feel the GPS locator is so restricting, allow us to click and pick from the map if the auto detection feature fails. | P35: I have nothing more to share
A36: 46178 | B36: NAIROBI | C36: NAIROBI WEST | D36: KIBRA-WESTLANDS | E36: MUTHANGARI PRIMARY SCHOOL - 04c27057-afdb-4450-995b-a56cdc08cf0e | G36: SL/SC | I36: Online (Link) | K36: Very Good | L36: Very Good | M36: Population data collection was completed successfully within the set timeline. The Kobo tool was easy to use and navigate. Data submission was smooth with minimal technical challenges. Support from the team was readily available when needed. | N36: Intermittent internet connectivity affected synchronization in some instances. Some respondents required additional clarification on the data collection requirements. A few delays were experienced during data verification. | O36: Provide refresher training before future data collection exercises. Improve communication on timelines and expectations. Enhance offline functionality and synchronization speed. Share clear data collection guidelines in advance. | P36: Thank you for the support throughout the exercise. The process was well coordinated and provided valuable learning opportunities for future data collection activities.
A37: 46178 | B37: NAIROBI | C37: NAIROBI WEST | D37: DAGORETTI-WESTLANDS | E37: GITIBA PRIMARY AND E.C.D.E SCHOOL - 63d5639a-94a6-43c3-b1a5-b1fef2de82f3 | G37: SL/SC | I37: Online (Link) | K37: Poor | L37: Good | M37: The school administration was very supportive in sharing the population data. | N37: Kindly provide a letter or document indicating that the request is from Food for Education. This makes it easier when presenting it to the school administration, as they will clearly understand that it is an official request from F4E. | O37: Kindly provide a letter or document indicating that the request is from Food for Education. This makes it easier when presenting it to the school administration, as they will clearly understand that it is an official request from F4E.
A38: 46178 | B38: NAIROBI | C38: NAIROBI EAST | D38: KASARANI | E38: DANDORA DAY NURSERY - b1a11aad-0e1f-4c36-ab8d-7efe5c3a3c67 | G38: SL/SC | I38: Online (Link) | K38: Good | L38: Good | M38: My school being ECDE it's easy to identify who is not feeding and who is | N38: Show data for failed taps | O38: None | P38: None
A39: 46178 | B39: KIAMBU | C39: KIAMBU CENTRAL | D39: GITHUNGURI 1 | E39: MATHANJA PRIMARY SCHOOL - 8e59cca9-4a08-409f-8f9d-86bcf0cf8b40 | G39: SL/SC | I39: Online (Link) | K39: Very Good | L39: Very Good | M39: The fact that the totals were calculated easily | N39: Baseline population not all schools keep the records | O39: Avoid boys and girls total instead we write the total per class
A40: 46178 | B40: KISUMU | C40: WESTERN - KISUMU | D40: KISUMU | E40: KIBUYE MIXED PRIMARY SCHOOL - ce37a0bd-570c-4b7d-b9a8-b440f064790e | G40: SL/SC | I40: Online (Link) | K40: Good | L40: Good | M40: Collecting data per class | N40: To improve on efficiency of online link. Sometimes it's abit slow. | O40: To allow app to work offline | P40: I appreciate the app it more efficient than link.
...

Sheet clean data
A1: Date | B1: County | C1: Region | D1: Subregion | E1: School | F1: School Name Length | G1: Please select your role | H1: Which mode of data collection in Kobo did you use? | I1: How would you rate the overall data collection process? | J1: How would you rate the overall use of the tool? | K1: Process score | L1: Total Score | M1: Follow-up Required | N1: What went well? | O1: What could have been better? | P1: How can we improve? | Q1: Any other notes or comments
A2: 46178 | B2: KIAMBU | C2: KIAMBU CENTRAL | D2: LIMURU 1 | E2: NYATARAGI PRIMARY | F2: =LEN(E2) -> 17 | G2: SL/SC | H2: Online (Link) | I2: Good | J2: Good | K2: =IF(I2="Very Good",4,IF(I2="Good",3,IF(I2="Poor",2,IF(I2="Very Poor",1,"")))) -> 3 | L2: =IF(J2="Very Good",4,IF(J2="Good",3,IF(J2="Poor",2,IF(J2="Very Poor",1,"")))) -> 3 | M2: =IF(OR(I2="Poor",I2="Very Poor"),"YES","") | N2: I was able to collect data on time so easily | O2: Getting the baseline population | Y2: =COUNTBLANK(Q2:Q590) -> 378
A3: 46178 | B3: KISUMU | C3: WESTERN KISUMU | D3: KISUMU | E3: ST JOHN PAUL KUDHO PRIMARY ECDE AND JUNIOR SECONDARY | F3: =LEN(E3) -> 52 | G3: SL/SC | H3: Online (Link) | I3: Very Good | J3: Very Good | K3: =IF(I3="Very Good",4,IF(I3="Good",3,IF(I3="Poor",2,IF(I3="Very Poor",1,"")))) -> 4 | L3: =IF(J3="Very Good",4,IF(J3="Good",3,IF(J3="Poor",2,IF(J3="Very Poor",1,"")))) -> 4 | M3: =IF(OR(I3="Poor",I3="Very Poor"),"YES","") | N3: It's very fast | P3: We should be given enough time | Q3: Good work
A4: 46178 | B4: KIAMBU | C4: KIAMBU WEST | D4: KIKUYU | E4: WAMBAA PRIMARY SCHOOL | F4: =LEN(E4) -> 21 | G4: SL/SC | H4: Online (Link) | I4: Good | J4: Good | K4: =IF(I4="Very Good",4,IF(I4="Good",3,IF(I4="Poor",2,IF(I4="Very Poor",1,"")))) -> 3 | L4: =IF(J4="Very Good",4,IF(J4="Good",3,IF(J4="Poor",2,IF(J4="Very Poor",1,"")))) -> 3 | M4: =IF(OR(I4="Poor",I4="Very Poor"),"YES","") | N4: Summation of the total students were done automatically | O4: The daily attendance report has been quite tricky to take since not all teachers are ready to cooperateOne day I went to get the attendance and was told attendance is same as yesterday yet the class had alot of empty seats | P4: Simple totals section instead of the boys and girls totals
A5: 46178 | B5: KIAMBU | C5: KIAMBU EAST | D5: KIAMBU | E5: KANGOYA PRIMARY AND JUNIOR SCHOOL | F5: =LEN(E5) -> 33 | G5: SL/SC | H5: Online (Link) | I5: Good | J5: Good | K5: =IF(I5="Very Good",4,IF(I5="Good",3,IF(I5="Poor",2,IF(I5="Very Poor",1,"")))) -> 3 | L5: =IF(J5="Very Good",4,IF(J5="Good",3,IF(J5="Poor",2,IF(J5="Very Poor",1,"")))) -> 3 | M5: =IF(OR(I5="Poor",I5="Very Poor"),"YES","") | N5: Great cooperation with the administration | O5: High rates of Abesentim really affects the accuracy of the data collected | P5: Good relations for accurate data with the administration
A6: 46178 | B6: KIAMBU | C6: KIAMBU WEST | D6: KIKUYU | E6: GIKAMBURA PRIMARY AND JUNIOR SCHOOL | F6: =LEN(E6) -> 35 | G6: SL/SC | H6: Offline (Used the app) | I6: Good | J6: Good | K6: =IF(I6="Very Good",4,IF(I6="Good",3,IF(I6="Poor",2,IF(I6="Very Poor",1,"")))) -> 3 | L6: =IF(J6="Very Good",4,IF(J6="Good",3,IF(J6="Poor",2,IF(J6="Very Poor",1,"")))) -> 3 | M6: =IF(OR(I6="Poor",I6="Very Poor"),"YES","") | N6: Seamless vigation | O6: GPS location was challenging
A7: 46178 | B7: KAJIADO | C7: NAIROBI WEST | D7: KAJIADOm LANGATA | E7: NGONG TOWNSHIP COMPREHENSIVE | F7: =LEN(E7) -> 28 | G7: SL/SC | H7: Online (Link) | I7: Very Good | J7: Very Good | K7: =IF(I7="Very Good",4,IF(I7="Good",3,IF(I7="Poor",2,IF(I7="Very Poor",1,"")))) -> 4 | L7: =IF(J7="Very Good",4,IF(J7="Good",3,IF(J7="Poor",2,IF(J7="Very Poor",1,"")))) -> 4 | M7: =IF(OR(I7="Poor",I7="Very Poor"),"YES","") | N7: Easier to use | O7: I like the layoutNo suggestion | P7: All is well
A8: 46178 | B8: KIAMBU | C8: KIAMBU EAST | D8: RUIRUJUJA | E8: ATHE PRIMARY AND JUNIOR SECONDARY SCHOOL | F8: =LEN(E8) -> 40 | G8: SL/SC | H8: Offline (Used the app) | I8: Very Good | J8: Very Good | K8: =IF(I8="Very Good",4,IF(I8="Good",3,IF(I8="Poor",2,IF(I8="Very Poor",1,"")))) -> 4 | L8: =IF(J8="Very Good",4,IF(J8="Good",3,IF(J8="Poor",2,IF(J8="Very Poor",1,"")))) -> 4 | M8: =IF(OR(I8="Poor",I8="Very Poor"),"YES","") | N8: It's easy to use as I just key in the number of kids in every class and it calculate the overall population | O8: The app is friendly and easy to use | P8: It would be nice if we could receive airtime during the period of data collection and other assignments so as it can be efficient more
A9: 46178 | B9: KIAMBU | C9: KIAMBU WEST | D9: KABETE | E9: RUKUBI COMPREHENSIVE SCHOOL | F9: =LEN(E9) -> 27 | G9: SL/SC | H9: Offline (Used the app) | I9: Very Good | J9: Very Good | K9: =IF(I9="Very Good",4,IF(I9="Good",3,IF(I9="Poor",2,IF(I9="Very Poor",1,"")))) -> 4 | L9: =IF(J9="Very Good",4,IF(J9="Good",3,IF(J9="Poor",2,IF(J9="Very Poor",1,"")))) -> 4 | M9: =IF(OR(I9="Poor",I9="Very Poor"),"YES","") | N9: It was an easy task | O9: Everything was ok on my side | P9: so far
A10: 46178 | B10: KIAMBU | C10: KIAMBU EAST | D10: RUIRU GITHUNGURI | E10: ST GEORGE'S COMPREHENSIVE SCHOOL | F10: =LEN(E10) -> 32 | G10: SL/SC | H10: Online (Link) | I10: Good | J10: Good | K10: =IF(I10="Very Good",4,IF(I10="Good",3,IF(I10="Poor",2,IF(I10="Very Poor",1,"")))) -> 3 | L10: =IF(J10="Very Good",4,IF(J10="Good",3,IF(J10="Poor",2,IF(J10="Very Poor",1,"")))) -> 3 | M10: =IF(OR(I10="Poor",I10="Very Poor"),"YES","") | N10: It was easy to use | O10: Ensure smooth transfer where when you send the data it doesn’t take you back to start afresh | P10: Ensure smooth running
A11: 46178 | B11: KAKAMEGA | C11: WESTERN KAKAMEGA | D11: KAKAMEGA | E11: MWIYALA COMPREHENSIVE PRIMARY | F11: =LEN(E11) -> 29 | G11: SL/SC | H11: Offline (Used the app) | I11: Good | J11: Good | K11: =IF(I11="Very Good",4,IF(I11="Good",3,IF(I11="Poor",2,IF(I11="Very Poor",1,"")))) -> 3 | L11: =IF(J11="Very Good",4,IF(J11="Good",3,IF(J11="Poor",2,IF(J11="Very Poor",1,"")))) -> 3 | M11: =IF(OR(I11="Poor",I11="Very Poor"),"YES","") | N11: It's fast and more convenient | O11: Logging in sometimes is a problem | P11: Saving logging in details to avoid going through the whole process again when you want to feed in data
A12: 46178 | B12: KIAMBU | C12: KIAMBU CENTRAL | D12: LIMURU 1 | E12: THIGIO PRIMARY SCHOOL | F12: =LEN(E12) -> 21 | G12: SL/SC | H12: Online (Link) | I12: Good | J12: Good | K12: =IF(I12="Very Good",4,IF(I12="Good",3,IF(I12="Poor",2,IF(I12="Very Poor",1,"")))) -> 3 | L12: =IF(J12="Very Good",4,IF(J12="Good",3,IF(J12="Poor",2,IF(J12="Very Poor",1,"")))) -> 3 | M12: =IF(OR(I12="Poor",I12="Very Poor"),"YES","") | N12: It's quite easy to maneuver And one cannot loose data once you leave the site | O12: I was uble to access the maps coordites on my phone thus had to use the termil
A13: 46178 | B13: NAIROBI | C13: NAIROBI EAST | D13: EMBAKASI | E13: NCC EMBAKASI COMPREHENSIVE SCHOOL | F13: =LEN(E13) -> 33 | G13: SL/SC | H13: Offline (Used the app) | I13: Good | J13: Good | K13: =IF(I13="Very Good",4,IF(I13="Good",3,IF(I13="Poor",2,IF(I13="Very Poor",1,"")))) -> 3 | L13: =IF(J13="Very Good",4,IF(J13="Good",3,IF(J13="Poor",2,IF(J13="Very Poor",1,"")))) -> 3 | M13: =IF(OR(I13="Poor",I13="Very Poor"),"YES","") | N13: The process of collecting was made easy because the documents were available | O13: Co ordition among teachers when collecting the registers | P13: Easy acquiring of the registers
A14: 46178 | B14: KAJIADO | C14: NAIROBI WEST | D14: KAJIADO LANGATA | E14: OLOOLUA COMPREHENSIVE SCHOOL | F14: =LEN(E14) -> 28 | G14: SL/SC | H14: Online (Link) | I14: Good | J14: Very Good | K14: =IF(I14="Very Good",4,IF(I14="Good",3,IF(I14="Poor",2,IF(I14="Very Poor",1,"")))) -> 3 | L14: =IF(J14="Very Good",4,IF(J14="Good",3,IF(J14="Poor",2,IF(J14="Very Poor",1,"")))) -> 4 | M14: =IF(OR(I14="Poor",I14="Very Poor"),"YES","") | N14: Comparing the total daily attendance and the total meals served daily as it is crucial to find the percentage of feeding kids | O14: Collection of daily school attendance is challenging as some teachers don't update their registers daily | P14: All is good
A15: 46178 | B15: NAIROBI | C15: NAIROBI EAST | D15: EMBAKASI | E15: NAIROBI SOUTH PRIMARY | F15: =LEN(E15) -> 21 | G15: SL/SC | H15: Online (Link) | I15: Good | J15: Good | K15: =IF(I15="Very Good",4,IF(I15="Good",3,IF(I15="Poor",2,IF(I15="Very Poor",1,"")))) -> 3 | L15: =IF(J15="Very Good",4,IF(J15="Good",3,IF(J15="Poor",2,IF(J15="Very Poor",1,"")))) -> 3 | M15: =IF(OR(I15="Poor",I15="Very Poor"),"YES","") | N15: Everything went on well without any hitches experienced
A16: 46178 | B16: NAIROBI | C16: NAIROBI EAST | D16: KASARANI | E16: TOM MBOYA PRIMARY AND JUNIOR SECONDRAY SCHOOL | F16: =LEN(E16) -> 45 | G16: SL/SC | H16: Online (Link) | I16: Good | J16: Good | K16: =IF(I16="Very Good",4,IF(I16="Good",3,IF(I16="Poor",2,IF(I16="Very Poor",1,"")))) -> 3 | L16: =IF(J16="Very Good",4,IF(J16="Good",3,IF(J16="Poor",2,IF(J16="Very Poor",1,"")))) -> 3 | M16: =IF(OR(I16="Poor",I16="Very Poor"),"YES","") | N16: Thwe option for entering just the total beside per class population | O16: Excluding the baseline population | P16: Exclude the baseline population | Q16: So far so good
A17: 46178 | B17: KIAMBU | C17: KIAMBU EAST | D17: RUIRU JUJA | E17: ST FRANCIS MUGAI COMPREHENSIVE PRIMARY | F17: =LEN(E17) -> 38 | G17: SL/SC | H17: Offline (Used the app) | I17: Good | J17: Very Good | K17: =IF(I17="Very Good",4,IF(I17="Good",3,IF(I17="Poor",2,IF(I17="Very Poor",1,"")))) -> 3 | L17: =IF(J17="Very Good",4,IF(J17="Good",3,IF(J17="Poor",2,IF(J17="Very Poor",1,"")))) -> 4 | M17: =IF(OR(I17="Poor",I17="Very Poor"),"YES","") | N17: The app was really efficient | O17: Collecting the registers some teachers took long to submit | P17: An official document highlighting why we need the register could help speed up the process
A18: 46178 | B18: KIAMBU | C18: KIAMBU CENTRAL | D18: GITHUNGURI 1 | E18: GATHAITHI SECONDARY SCHOOL | F18: =LEN(E18) -> 26 | G18: Highschool Tapper | H18: Online (Link) | I18: Good | J18: Good | K18: =IF(I18="Very Good",4,IF(I18="Good",3,IF(I18="Poor",2,IF(I18="Very Poor",1,"")))) -> 3 | L18: =IF(J18="Very Good",4,IF(J18="Good",3,IF(J18="Poor",2,IF(J18="Very Poor",1,"")))) -> 3 | M18: =IF(OR(I18="Poor",I18="Very Poor"),"YES","") | N18: I was eble to notice the overall school attendance per day | O18: If the population was more | P18: Create a site where we could get the percentage of attending students over the school's total population
A19: 46178 | B19: MOMBASA | C19: COAST | D19: NYALI MOMBASA | E19: BEDZIMBA COMPREHENSIVE SCHOOL | F19: =LEN(E19) -> 29 | G19: SL/SC | H19: Offline (Used the app) | I19: Good | J19: Very Good | K19: =IF(I19="Very Good",4,IF(I19="Good",3,IF(I19="Poor",2,IF(I19="Very Poor",1,"")))) -> 3 | L19: =IF(J19="Very Good",4,IF(J19="Good",3,IF(J19="Poor",2,IF(J19="Very Poor",1,"")))) -> 4 | M19: =IF(OR(I19="Poor",I19="Very Poor"),"YES","") | N19: Data was captured fast but it would save time and accuracy if most of the parts were put in the same page ie categorised into ECD primary and junior school | O19: A fewer pages would be great | P19: Compile the pages to make them a few like ECD pages primary pageand jss page | Q19: All went well ✅👏🏿
A20: 46178 | B20: KIAMBU | C20: KIAMBU WEST | D20: KIKUYU | E20: PCEA MAMA NGI KENYATTA COMPREHENSIVE | F20: =LEN(E20) -> 36 | G20: SL/SC | H20: Offline (Used the app) | I20: Good | J20: Good | K20: =IF(I20="Very Good",4,IF(I20="Good",3,IF(I20="Poor",2,IF(I20="Very Poor",1,"")))) -> 3 | L20: =IF(J20="Very Good",4,IF(J20="Good",3,IF(J20="Poor",2,IF(J20="Very Poor",1,"")))) -> 3 | M20: =IF(OR(I20="Poor",I20="Very Poor"),"YES","") | N20: That's a good tracking of the feeding growth | O20: For me the head of institution declined to give me population thus requesting for a better communication with the head of institution for a professiol documents to support the population collection | P20: In the schools that are declining to give the population then there should be a more conquering documents to request for a population | Q20: No
A21: 46178 | B21: MOMBASA | C21: COAST | D21: NYALI MOMBASA | E21: KONGOWEA PRIMARY SCHOOL | F21: =LEN(E21) -> 23 | G21: SL/SC | H21: Online (Link) | I21: Very Good | J21: Very Good | K21: =IF(I21="Very Good",4,IF(I21="Good",3,IF(I21="Poor",2,IF(I21="Very Poor",1,"")))) -> 4 | L21: =IF(J21="Very Good",4,IF(J21="Good",3,IF(J21="Poor",2,IF(J21="Very Poor",1,"")))) -> 4 | M21: =IF(OR(I21="Poor",I21="Very Poor"),"YES","") | N21: It was so accurate | O21: Apart from it being efficient and fast I don't see any change that will make it more better than it is at the moment | P21: Everything is topnotch thank you team | Q21: All is well
A22: 46178 | B22: MOMBASA | C22: COAST | D22: NYALI MOMBASA | E22: MTOPANGA COMPREHENSIVE SCHOOL | F22: =LEN(E22) -> 29 | G22: SL/SC | H22: Offline (Used the app) | I22: Very Good | J22: Very Good | K22: =IF(I22="Very Good",4,IF(I22="Good",3,IF(I22="Poor",2,IF(I22="Very Poor",1,"")))) -> 4 | L22: =IF(J22="Very Good",4,IF(J22="Good",3,IF(J22="Poor",2,IF(J22="Very Poor",1,"")))) -> 4 | M22: =IF(OR(I22="Poor",I22="Very Poor"),"YES","") | N22: Everything went wellthe application is user friendly and the fact that you can save the data and edit before submitting that helps us so much | O22: Every thing was better on my side
A23: 46178 | B23: NAIROBI | C23: NAIROBI EAST | D23: KASARANI | E23: CHELETA PRIMARY SCHOOL | F23: =LEN(E23) -> 22 | G23: SL/SC | H23: Online (Link) | I23: Good | J23: Good | K23: =IF(I23="Very Good",4,IF(I23="Good",3,IF(I23="Poor",2,IF(I23="Very Poor",1,"")))) -> 3 | L23: =IF(J23="Very Good",4,IF(J23="Good",3,IF(J23="Poor",2,IF(J23="Very Poor",1,"")))) -> 3 | M23: =IF(OR(I23="Poor",I23="Very Poor"),"YES","") | N23: At some point i could my school location was not picking the latitude the location pick up was the major hinderance | O23: App is clear and to the point | P23: Enhance quick access for location | Q23: Good collection tool
A24: 46178 | B24: NAIROBI | C24: NAIROBI WEST | D24: KIBRAWESTLANDS | E24: ARYA PRIMARY SCHOOL | F24: =LEN(E24) -> 19 | G24: SL/SC | H24: Online (Link) | I24: Very Good | J24: Very Good | K24: =IF(I24="Very Good",4,IF(I24="Good",3,IF(I24="Poor",2,IF(I24="Very Poor",1,"")))) -> 4 | L24: =IF(J24="Very Good",4,IF(J24="Good",3,IF(J24="Poor",2,IF(J24="Very Poor",1,"")))) -> 4 | M24: =IF(OR(I24="Poor",I24="Very Poor"),"YES","") | N24: The process was easy by the help of the kopo data collection tool it was easy because after getting the data from the admin I was only feeding it to the tool | O24: Maybe next time you give us more time because sometimes after collecting data you find that there are other students who wants to be admitted in school Maybe next time we should submit data after midterm | P24: Add more time to the data collection exercise | Q24: It was a smooth exercise
A25: 46178 | B25: MOMBASA | C25: COAST | D25: NYALI MOMBASA | E25: AZHAR SHARRIF COMPREHENSIVE SCHOOL | F25: =LEN(E25) -> 34 | G25: SL/SC | H25: Online (Link) | I25: Very Good | J25: Very Good | K25: =IF(I25="Very Good",4,IF(I25="Good",3,IF(I25="Poor",2,IF(I25="Very Poor",1,"")))) -> 4 | L25: =IF(J25="Very Good",4,IF(J25="Good",3,IF(J25="Poor",2,IF(J25="Very Poor",1,"")))) -> 4 | M25: =IF(OR(I25="Poor",I25="Very Poor"),"YES","") | N25: the whole process went well | P25: Scale fusion is preventing the use of Kobocollect
A26: 46178 | B26: MOMBASA | C26: COAST | D26: GOME MOMBASA | E26: LONGO PRIMARY SCHOOL | F26: =LEN(E26) -> 20 | G26: SL/SC | H26: Online (Link) | I26: Good | J26: Good | K26: =IF(I26="Very Good",4,IF(I26="Good",3,IF(I26="Poor",2,IF(I26="Very Poor",1,"")))) -> 3 | L26: =IF(J26="Very Good",4,IF(J26="Good",3,IF(J26="Poor",2,IF(J26="Very Poor",1,"")))) -> 3 | M26: =IF(OR(I26="Poor",I26="Very Poor"),"YES","") | N26: Teachers cooperation was of top notch | O26: The app had problem in submitting the data | P26: Make it better
A27: 46178 | B27: BUNGOMA | C27: WESTERN BUNGOMA | D27: BUNGOMA | E27: SIRITANYI RC COMPREHENSIVE SCHOOL | F27: =LEN(E27) -> 33 | G27: SL/SC | H27: Offline (Used the app) | I27: Very Good | J27: Very Good | K27: =IF(I27="Very Good",4,IF(I27="Good",3,IF(I27="Poor",2,IF(I27="Very Poor",1,"")))) -> 4 | L27: =IF(J27="Very Good",4,IF(J27="Good",3,IF(J27="Poor",2,IF(J27="Very Poor",1,"")))) -> 4 | M27: =IF(OR(I27="Poor",I27="Very Poor"),"YES","") | N27: This round it was sufficient no more searching errors unlike the one we used in first term | O27: Transfers of kids coming in and some some getting to other schools | P27: It should capture longitude anywhereas long as you are in school compound not necessarily at the gate
A28: 46178 | B28: KIAMBU | C28: KIAMBU WEST | D28: KIKUYU | E28: NGURIUNDITU PRIMARY AND JUNIOR SCHOOL | F28: =LEN(E28) -> 37 | G28: SL/SC | H28: Online (Link) | I28: Good | J28: Good | K28: =IF(I28="Very Good",4,IF(I28="Good",3,IF(I28="Poor",2,IF(I28="Very Poor",1,"")))) -> 3 | L28: =IF(J28="Very Good",4,IF(J28="Good",3,IF(J28="Poor",2,IF(J28="Very Poor",1,"")))) -> 3 | M28: =IF(OR(I28="Poor",I28="Very Poor"),"YES","") | N28: Mine was fastalthough I haven't tried doing it offline | O28: It would be better if you asked us the overall number instead of ' number of boys and girls per class' | P28: Already said in the previous question | Q28: Collecting the data daily is not working since we are being asked too much questions and it's becoming hectic I propose we collect data may be once per month
A29: 46178 | B29: MOMBASA | C29: COAST | D29: NYALI MOMBASA | E29: MAWENI PRIMARY SCHOOL | F29: =LEN(E29) -> 21 | G29: SL/SC | H29: Offline (Used the app) | I29: Very Good | J29: Very Good | K29: =IF(I29="Very Good",4,IF(I29="Good",3,IF(I29="Poor",2,IF(I29="Very Poor",1,"")))) -> 4 | L29: =IF(J29="Very Good",4,IF(J29="Good",3,IF(J29="Poor",2,IF(J29="Very Poor",1,"")))) -> 4 | M29: =IF(OR(I29="Poor",I29="Very Poor"),"YES","") | N29: It was easythe location was easy to allocate | P29: All was well | Q29: It easy to operate and easy to understand
A30: 46178 | B30: KIAMBU | C30: KIAMBU CENTRAL | D30: LIMURU 1 | E30: TIEKUNU PRIMARY SCHOOL | F30: =LEN(E30) -> 22 | G30: SL/SC | H30: Offline (Used the app) | I30: Very Good | J30: Good | K30: =IF(I30="Very Good",4,IF(I30="Good",3,IF(I30="Poor",2,IF(I30="Very Poor",1,"")))) -> 4 | L30: =IF(J30="Very Good",4,IF(J30="Good",3,IF(J30="Poor",2,IF(J30="Very Poor",1,"")))) -> 3 | M30: =IF(OR(I30="Poor",I30="Very Poor"),"YES","") | N30: Automatic calculation of numberseasy to use both online and offlinesaves unsent data in drafts to load later | O30: Using offline maps since no easy offline from exact location | P30: So far so goodits easy to use
A31: 46178 | B31: KISUMU | C31: WESTERN KISUMU | D31: KISUMU | E31: KIBOS PRISON COMPREHENSIVE SCHOOL | F31: =LEN(E31) -> 33 | G31: SL/SC | H31: Offline (Used the app) | I31: Very Good | J31: Very Good | K31: =IF(I31="Very Good",4,IF(I31="Good",3,IF(I31="Poor",2,IF(I31="Very Poor",1,"")))) -> 4 | L31: =IF(J31="Very Good",4,IF(J31="Good",3,IF(J31="Poor",2,IF(J31="Very Poor",1,"")))) -> 4 | M31: =IF(OR(I31="Poor",I31="Very Poor"),"YES","") | N31: The Kobo app is faster and easier to use since you can still save your work as draft and come back to continue | O31: Improve on location pick up the app was a bit slower on picking the GPS | P31: No recommendations for now | Q31: Collection of data has been made more easier compared to previous times were we had to take pictures from registers and scan then send
A32: 46178 | B32: MOMBASA | C32: COAST | D32: NYALI MOMBASA | E32: KISAUNI PRIMARY SCHOOL | F32: =LEN(E32) -> 22 | G32: SL/SC | H32: Offline (Used the app) | I32: Good | J32: Good | K32: =IF(I32="Very Good",4,IF(I32="Good",3,IF(I32="Poor",2,IF(I32="Very Poor",1,"")))) -> 3 | L32: =IF(J32="Very Good",4,IF(J32="Good",3,IF(J32="Poor",2,IF(J32="Very Poor",1,"")))) -> 3 | M32: =IF(OR(I32="Poor",I32="Very Poor"),"YES","") | N32: Easy to use | O32: Accessibility was a bit hard at first
A33: 46178 | B33: KIAMBU | C33: KIAMBU CENTRAL | D33: GITHUNGURI 2 | E33: KAMONDO PRIMARY AND JUNIOR SCHOOL | F33: =LEN(E33) -> 33 | G33: SL/SC | H33: Online (Link) | I33: Very Good | J33: Very Good | K33: =IF(I33="Very Good",4,IF(I33="Good",3,IF(I33="Poor",2,IF(I33="Very Poor",1,"")))) -> 4 | L33: =IF(J33="Very Good",4,IF(J33="Good",3,IF(J33="Poor",2,IF(J33="Very Poor",1,"")))) -> 4 | M33: =IF(OR(I33="Poor",I33="Very Poor"),"YES","") | N33: The link is easier to use compared to the app It provides a more direct process as users can submit the form immediately after completing the required fields without having to save it first before sending | Q33: No
A34: 46178 | B34: NAIROBI | C34: NAIROBI WEST | D34: KIBRA WESTLANDS | E34: ARYA PRIMARY SCHOOL | F34: =LEN(E34) -> 19 | G34: SL/SC | H34: Online (Link) | I34: Very Good | J34: Very Good | K34: =IF(I34="Very Good",4,IF(I34="Good",3,IF(I34="Poor",2,IF(I34="Very Poor",1,"")))) -> 4 | L34: =IF(J34="Very Good",4,IF(J34="Good",3,IF(J34="Poor",2,IF(J34="Very Poor",1,"")))) -> 4 | M34: =IF(OR(I34="Poor",I34="Very Poor"),"YES","") | N34: The exercise was easy by the help of the kopo tool | O34: It could be even better if u extended the data collection exercise to after midterm so as to capture all the students some get admitted late | P34: Add more time to the exercise | Q34: It was a smooth process
A35: 46178 | B35: NAIROBI | C35: NAIROBI EAST | D35: KASARANI | E35: DANDORA 1 PRIMARY AND JUNIOR SCHOOL | F35: =LEN(E35) -> 35 | G35: SL/SC | H35: Online (Link) | I35: Poor | J35: Poor | K35: =IF(I35="Very Good",4,IF(I35="Good",3,IF(I35="Poor",2,IF(I35="Very Poor",1,"")))) -> 2 | L35: =IF(J35="Very Good",4,IF(J35="Good",3,IF(J35="Poor",2,IF(J35="Very Poor",1,"")))) -> 2 | M35: =IF(OR(I35="Poor",I35="Very Poor"),"YES","") -> YES | N35: I was able to feed all the population data | O35: I worked with the kobo app at first after filling all the detailsand tried to submit I got an error saying form is not active Getting school GPS wasn't easier despite the fact that I was standing right at the school gate I'm not even sure if the coordites sent were accurate After resorting to the online form the major challenge was that I couldn't see what I was selecting as region subregion and school it's best if the wording appear clearly not just some random circles | P35: When you update the population collection tool on the app please do us the courtesy of informing us so we can update as required On the attachment allow inclusion of more than 1 file type as well as multiple files I didn't attach the evidence given by the ECDE Mager because there was no way to add it In the list of source of information you left out the ECDE mager yet they are crucial in information provision again allow us to choose more than 1 source of information I persolly feel the GPS locator is so restricting allow us to click and pick from the map if the auto detection feature fails | Q35: I have more to share
A36: 46178 | B36: NAIROBI | C36: NAIROBI WEST | D36: KIBRA WESTLANDS | E36: MUTHANGARI PRIMARY SCHOOL | F36: =LEN(E36) -> 25 | G36: SL/SC | H36: Online (Link) | I36: Very Good | J36: Very Good | K36: =IF(I36="Very Good",4,IF(I36="Good",3,IF(I36="Poor",2,IF(I36="Very Poor",1,"")))) -> 4 | L36: =IF(J36="Very Good",4,IF(J36="Good",3,IF(J36="Poor",2,IF(J36="Very Poor",1,"")))) -> 4 | M36: =IF(OR(I36="Poor",I36="Very Poor"),"YES","") | N36: Population data collection was completed successfully within the set timeline The Kobo tool was easy to use and vigate Data submission was smooth with minimal technical challenges Support from the team was readily available when needed | O36: Intermittent internet connectivity affected synchronization in some instances Some respondents required additiol clarification on the data collection requirements A few delays were experienced during data verification | P36: Provide refresher training before future data collection exercises Improve communication on timelines and expectations Enhance offline functiolity and synchronization speed Share clear data collection guidelines in advance | Q36: Thank you for the support throughout the exercise The process was well coordited and provided valuable learning opportunities for future data collection activities
A37: 46178 | B37: NAIROBI | C37: NAIROBI WEST | D37: DAGORETTI WESTLANDS | E37: GITIBA PRIMARY AND ECDE SCHOOL | F37: =LEN(E37) -> 30 | G37: SL/SC | H37: Online (Link) | I37: Poor | J37: Good | K37: =IF(I37="Very Good",4,IF(I37="Good",3,IF(I37="Poor",2,IF(I37="Very Poor",1,"")))) -> 2 | L37: =IF(J37="Very Good",4,IF(J37="Good",3,IF(J37="Poor",2,IF(J37="Very Poor",1,"")))) -> 3 | M37: =IF(OR(I37="Poor",I37="Very Poor"),"YES","") -> YES | N37: The school administration was very supportive in sharing the population data | O37: Kindly provide a letter or document indicating that the request is from Food for Education This makes it easier when presenting it to the school administration as they will clearly understand that it is an official request from F4E | P37: Kindly provide a letter or document indicating that the request is from Food for Education This makes it easier when presenting it to the school administration as they will clearly understand that it is an official request from F4E
A38: 46178 | B38: NAIROBI | C38: NAIROBI EAST | D38: KASARANI | E38: DANDORA DAY NURSERY | F38: =LEN(E38) -> 19 | G38: SL/SC | H38: Online (Link) | I38: Good | J38: Good | K38: =IF(I38="Very Good",4,IF(I38="Good",3,IF(I38="Poor",2,IF(I38="Very Poor",1,"")))) -> 3 | L38: =IF(J38="Very Good",4,IF(J38="Good",3,IF(J38="Poor",2,IF(J38="Very Poor",1,"")))) -> 3 | M38: =IF(OR(I38="Poor",I38="Very Poor"),"YES","") | N38: My school being ECDE it's easy to identify who is not feeding and who is | O38: Show data for failed taps
A39: 46178 | B39: KIAMBU | C39: KIAMBU CENTRAL | D39: GITHUNGURI 1 | E39: MATHANJA PRIMARY SCHOOL | F39: =LEN(E39) -> 23 | G39: SL/SC | H39: Online (Link) | I39: Very Good | J39: Very Good | K39: =IF(I39="Very Good",4,IF(I39="Good",3,IF(I39="Poor",2,IF(I39="Very Poor",1,"")))) -> 4 | L39: =IF(J39="Very Good",4,IF(J39="Good",3,IF(J39="Poor",2,IF(J39="Very Poor",1,"")))) -> 4 | M39: =IF(OR(I39="Poor",I39="Very Poor"),"YES","") | N39: The fact that the totals were calculated easily | O39: Baseline population not all schools keep the records | P39: Avoid boys and girls total instead we write the total per class
A40: 46178 | B40: KISUMU | C40: WESTERN KISUMU | D40: KISUMU | E40: KIBUYE MIXED PRIMARY SCHOOL | F40: =LEN(E40) -> 27 | G40: SL/SC | H40: Online (Link) | I40: Good | J40: Good | K40: =IF(I40="Very Good",4,IF(I40="Good",3,IF(I40="Poor",2,IF(I40="Very Poor",1,"")))) -> 3 | L40: =IF(J40="Very Good",4,IF(J40="Good",3,IF(J40="Poor",2,IF(J40="Very Poor",1,"")))) -> 3 | M40: =IF(OR(I40="Poor",I40="Very Poor"),"YES","") | N40: Collecting data per class | O40: To improve on efficiency of online link Sometimes it's abit slow | P40: To allow app to work offline | Q40: I appreciate the app it more efficient than link
...

Sheet Pivot Tables
E3: Count of School | F3: Column Labels | L3: Count of School | M3: Column Labels | Q3: Count of School | R3: Column Labels
E4: Row Labels | F4: Good | G4: Very Good | H4: Poor | I4: Very Poor | J4: Grand Total | L4: Row Labels | M4: Offline (Used the app) | N4: Online (Link) | O4: Grand Total | Q4: Row Labels | R4: Good | S4: Poor | T4: Very Good | U4: Very Poor | V4: Grand Total
E5: NAKURU | F5: 2 | G5: 1 | J5: 3 | L5: WESTERN NAKURU | M5: 2 | N5: 1 | O5: 3 | Q5: SL/SC | R5: 233 | S5: 5 | T5: 188 | U5: 2 | V5: 428
E6: MACHAKOS | F6: 3 | G6: 1 | J6: 4 | L6: WESTERN KAKAMEGA | M6: 25 | N6: 1 | O6: 26 | Q6: KO | R6: 51 | S6: 1 | T6: 22 | U6: 1 | V6: 75
E7: KAJIADO | F7: 4 | G7: 2 | J7: 6 | L7: WESTERN BUNGOMA | M7: 18 | N7: 11 | O7: 29 | Q7: Server | R7: 37 | S7: 2 | T7: 10 | U7: 1 | V7: 50
E8: NYERI | F8: 8 | G8: 3 | H8: 2 | J8: 13 | L8: COAST | M8: 11 | N8: 12 | O8: 23 | Q8: Highschool Tapper | R8: 27 | T8: 8 | U8: 1 | V8: 36
E9: KISUMU | F9: 10 | G9: 11 | J9: 21 | L9: DECENTRALIZED CENTRAL NYERI | N9: 13 | O9: 13 | Q9: Grand Total | R9: 348 | S9: 8 | T9: 228 | U9: 5 | V9: 589
E10: MOMBASA | F10: 11 | G10: 12 | J10: 23 | L10: WESTERN KISUMU | M10: 8 | N10: 13 | O10: 21
E11: KAKAMEGA | F11: 13 | G11: 13 | J11: 26 | L11: KIAMBU EAST | M11: 16 | N11: 19 | O11: 35
E12: BUNGOMA | F12: 16 | G12: 13 | J12: 29 | L12: WESTERN UASINGISHU | M12: 21 | N12: 25 | O12: 46
E13: UASINGISHU | F13: 31 | G13: 15 | J13: 46 | L13: KIAMBU WEST | M13: 14 | N13: 35 | O13: 49
E14: MURANG'A | F14: 47 | G14: 11 | H14: 1 | I14: 2 | J14: 61 | L14: DECENTRALIZED CENTRAL MURANG'A | M14: 6 | N14: 55 | O14: 61 | Q14: Row Labels | R14: Sum of Total Score | S14: Sum of Process score
E15: KIAMBU | F15: 96 | G15: 69 | H15: 1 | I15: 1 | J15: 167 | L15: KIAMBU CENTRAL | M15: 13 | N15: 70 | O15: 83 | Q15: 4 | R15: 1128 | S15: 1040
E16: NAIROBI | F16: 107 | G16: 77 | H16: 4 | I16: 2 | J16: 190 | L16: NAIROBI WEST | M16: 13 | N16: 77 | O16: 90 | Q16: 3 | R16: 888 | S16: 913
E17: Grand Total | F17: 348 | G17: 228 | H17: 8 | I17: 5 | J17: 589 | L17: NAIROBI EAST | M17: 5 | N17: 105 | O17: 110 | Q17: 2 | R17: 14 | S17: 18
L18: Grand Total | M18: 152 | N18: 437 | O18: 589 | Q18: 1 | R18: 4 | S18: 6
Q19: Grand Total | R19: 2034 | S19: 1977
E20: Row Labels | F20: Average of Process score | L20: Count of School | M20: Column Labels
E21: NYERI | F21: 3.0769231 | L21: Row Labels | N21: YES | O21: Grand Total
E22: MURANG'A | F22: 3.0983607 | L22: BUNGOMA | M22: 29 | O22: 29
E23: MACHAKOS | F23: 3.25 | L23: KAJIADO | M23: 6 | O23: 6
E24: UASINGISHU | F24: 3.326087 | L24: KAKAMEGA | M24: 26 | O24: 26
E25: KAJIADO | F25: 3.3333333 | L25: KIAMBU | M25: 165 | N25: 2 | O25: 167
E26: NAKURU | F26: 3.3333333 | L26: KISUMU | M26: 21 | O26: 21
E27: NAIROBI | F27: 3.3631579 | L27: MACHAKOS | M27: 4 | O27: 4
E28: KIAMBU | F28: 3.3952096 | L28: MOMBASA | M28: 23 | O28: 23
E29: BUNGOMA | F29: 3.4482759 | L29: MURANG'A | M29: 58 | N29: 3 | O29: 61
E30: KAKAMEGA | F30: 3.5 | L30: NAIROBI | M30: 184 | N30: 6 | O30: 190
E31: MOMBASA | F31: 3.5217391 | L31: NAKURU | M31: 3 | O31: 3
E32: KISUMU | F32: 3.5238095 | L32: NYERI | M32: 11 | N32: 2 | O32: 13
E33: Grand Total | F33: 3.3565365 | L33: UASINGISHU | M33: 46 | O33: 46
L34: Grand Total | M34: 576 | N34: 13 | O34: 589

Sheet Dashboard 
B2: School Nutrition & Enrollment Insights — Regional Performance Dashboard
B3: Population Data Collection • Program Review • Multi-County Overview
B9: TOTAL RESPONDENTS | F9: COUNTIES COVERED | J9: POSITIVE RATING RATE | N9: FOLLOW - UP REQUIRED
B10: =GETPIVOTDATA("School ",'Pivot Tables'!$E$3) -> 589 | F10: =IF(COUNTA('Pivot Tables'!$E$4:$E$16)-2 > 1, 12, 1) -> 12 | J10: =(GETPIVOTDATA("School ",'Pivot Tables'!$E$3,"How would you rate the overall data collection process?","Very Good")+GETPIVOTDATA("School ",'Pivot Tables'!$E$3,"How would you rate the overall data collection process?","Good"))/GETPIVOTDATA("School ",'Pivot Tables'!$E$3) -> 0.97792869 | N10: =IFERROR(GETPIVOTDATA("School ",'Pivot Tables'!$L$20,"Follow-up Required","YES"),0) -> 13
B13: Field staff across Kenya | F13: Nairobi to Bungoma | J13: Good or Very Good | N13: Poor or Very Poor Rating
B16: Summary — 589 field staff completed population data collection across 12 counties. 97.8% rated the process positively. 13 schools require follow-up, with Nairobi accounting for 6 cases. Western Kakamega recorded the highest offline app usage.
K37: Follow-up required schools
K39: County | L39: Schools | M39: Priority
K40: {='Pivot Tables'!L22:L33} -> BUNGOMA | L40: {='Pivot Tables'!N22:N33} -> 0 | M40: =IF(L40>2, "Priority", "Monitor") -> Monitor
K41: KAJIADO | L41: 0 | M41: =IF(L41>2, "Priority", "Monitor") -> Monitor
K42: KAKAMEGA | L42: 0 | M42: =IF(L42>2, "Priority", "Monitor") -> Monitor
K43: KIAMBU | L43: 2 | M43: =IF(L43>2, "Priority", "Monitor") -> Monitor
K44: KISUMU | L44: 0 | M44: =IF(L44>2, "Priority", "Monitor") -> Monitor
K45: MACHAKOS | L45: 0 | M45: =IF(L45>2, "Priority", "Monitor") -> Monitor
K46: MOMBASA | L46: 0 | M46: =IF(L46>2, "Priority", "Monitor") -> Monitor
K47: MURANG'A | L47: 3 | M47: =IF(L47>2, "Priority", "Monitor") -> Priority
K48: NAIROBI | L48: 6 | M48: =IF(L48>2, "Priority", "Monitor") -> Priority
K49: NAKURU | L49: 0 | M49: =IF(L49>2, "Priority", "Monitor") -> Monitor
K50: NYERI | L50: 2 | M50: =IF(L50>2, "Priority", "Monitor") -> Monitor
K51: UASINGISHU | L51: 0 | M51: =IF(L51>2, "Priority", "Monitor") -> Monitor
